Workbook

Sheet Log
A1: Fall 2026 base block — daily log
A2: Blue = type here. Black = formula. Only edit the Done / Actual / RPE / How it felt columns.
A4: Date | B4: Day | C4: Wk | D4: Phase | E4: Category | F4: Session | G4: Planned | H4: Plan yd | I4: Plan km | J4: Done | K4: Act yd | L4: Act km | M4: Act min | N4: RPE | O4: How it felt | P4: What the session is
A5: 2026-09-21 | B5: Mon | C5: 1 | D5: reset | E5: swim | F5: Swim — CSS test (400 + 200 TT) | G5: 1,500 yd · 33–44 min | H5: 1500 | P5: Warm-up 400 (200 free, 4 × 50 drill). Build 4 × 50. Main: 400 yd all-out for time, 5 min full rest, then 200 yd all-out for time. Cool-down 300 easy. CSS seconds per 100 yd = (T400 − T200) ÷ 2. Write both times down — every send-off in this block comes from this number. Result, Sep 21: 7:06 and 3:20, giving CSS 1:53/100 yd.
A6: 2026-09-21 | B6: Mon | C6: 1 | D6: reset | E6: strength | F6: Strength A — RDL + posterior chain | G6: 45–55 min | P6: First session back. Leave two reps in reserve on everything — this is a re-entry week, not a test.
A7: 2026-09-22 | B7: Tue | C7: 1 | D7: reset | E7: run | F7: Easy run — 5 km | G7: 30–35 min | I7: 5 | P7: Track or soft trail, nothing paved. 140–152 bpm, cadence 175–180. This is the only run this week; resist adding another.
A8: 2026-09-22 | B8: Tue | C8: 1 | D8: reset | E8: mobility | F8: Mobility + lower-leg prehab | G8: 15 min | P8: Ankle dorsiflexion (knee-to-wall), calf and soleus stretch, hip flexors, thoracic rotation, and 3 × 20 tibialis raises. Ten minutes of this beats an hour once a month.
A9: 2026-09-23 | B9: Wed | C9: 1 | D9: reset | E9: swim | F9: Swim — technique reset with new gear | G9: 1,600 yd · 36–47 min | H9: 1600 | P9: Warm-up 300. Drill 600 as 12 × 50 with fins — each drill twice: catch-up / 6-1-6 left / 6-1-6 right / fingertip drag / side kick / single-arm. Snorkel for the face-down drills only; take it off for 6-1-6 and side kick, because on your side it floods. Main 10 × 50 on 1:15 aerobic, every 4th one breathing to the left. Cool-down 200. Getting the snorkel to feel normal is the whole job today.
A10: 2026-09-23 | B10: Wed | C10: 1 | D10: reset | E10: bike | F10: Spin bike — Z2 aerobic | G10: 45 min | P10: Keiser M3i, 130–145 bpm, cadence 85–95. Note your average watts — you will want the comparison after next week's FTP test. Result, Sep 23: 130–150 W at 140–150 bpm, level 12. Against the FTP that test went on to produce, 186 W, that is 70–81% — so the top half of this ride was tempo, not Z2, which is exactly what the heart rate was saying. Fine once, but these rides exist to add cheap aerobic volume, and if they cost recovery they start competing with the swim and run work that actually matter. Z2 is 104–140 W.
A11: 2026-09-24 | B11: Thu | C11: 1 | D11: reset | E11: cardio | F11: Optional shakeout walk or easy spin | G11: 25 min | P11: Only if the legs feel good after Tuesday. Walking counts. Nothing that loads the shins.
A12: 2026-09-24 | B12: Thu | C12: 1 | D12: reset | E12: mobility | F12: Mobility + lower-leg prehab | G12: 20 min | P12: Longer mobility session: hips, ankles, calves, and thoracic spine. Add 3 × 45 s soleus wall sits.
A13: 2026-09-25 | B13: Fri | C13: 1 | D13: reset | E13: swim | F13: Swim — long aerobic base | G13: 2,100 yd · 47–62 min | H13: 2100 | P13: Warm-up 300. Main: 1,000 continuous at genuine easy-aerobic (2:05–2:10/100). Then 6 × 100 on 2:30. Cool-down 200. Watch HR on the 1,000 — if it climbs more than ~15 bpm from start to finish, you went out too hard. That drift number is the benchmark we beat all block.
A14: 2026-09-26 | B14: Sat | C14: 1 | D14: reset | E14: cardio | F14: Weekend aerobic — long ride or hike | G14: 2–3 hr | P14: Your pick: 2–2.5 hr endurance ride or a 2–3 hr hike. Keep it genuinely aerobic; this is volume, not a workout.
A15: 2026-09-26 | B15: Sat | C15: 1 | D15: reset | E15: swim | F15: Technique swim (short) | G15: 1,000 yd · 22–29 min | H15: 1000 | P15: About 1,000 yd total, all easy. No clock, no main set. Snorkel and fins for the first half — catch-up, fingertip drag and front scull, rotating through them — then easy 50s holding the feel. This session exists to raise frequency and keep the stroke fresh — leave the pool fresher than you arrived.
A16: 2026-09-27 | B16: Sun | C16: 1 | D16: reset | E16: mobility | F16: Mobility + lower-leg prehab | G16: 25 min | P16: Full mobility session plus foot intrinsics: short-foot holds, towel scrunches, and heel/toe walks. Ten minutes of this on Sundays is what keeps the anterior compartment quiet.
A17: 2026-09-27 | B17: Sun | C17: 1 | D17: reset | E17: bike | F17: Easy spin (optional) | G17: 40–60 min | P17: Recovery spin only if you want the extra aerobic time. Zone 1–2, no intensity.
A18: 2026-09-28 | B18: Mon | C18: 2 | D18: reset | E18: swim | F18: Swim — threshold 10 × 100 | G18: 2,200 yd · 49–65 min | H18: 2200 | P18: Warm-up 400. Drill 400 as 8 × 50, each drill twice: catch-up / 6-1-6 / fingertip drag / side kick. Fins throughout; snorkel off for 6-1-6 and side kick. Main: 10 × 100 at CSS on 2:15 (about 22 s rest). Then 4 × 50 breaststroke easy. Cool-down 200. If you cannot hold the last three, the send-off is too tight — add 5 s, do not slow the swimming down.
A19: 2026-09-28 | B19: Mon | C19: 2 | D19: reset | E19: strength | F19: Strength A — RDL + posterior chain | G19: 45–55 min | P19: Second time through. Add load to the RDL if last week's felt easy, but keep the 3 s eccentric honest.
A20: 2026-09-29 | B20: Tue | C20: 2 | D20: reset | E20: run | F20: Easy run — 6 km + strides | G20: 35–40 min | I20: 6 | P20: Track or soft trail. Finish with 4 × 20 s strides on grass, full recovery between. Strides build tendon stiffness without adding volume — they are the safest speed you can do right now.
A21: 2026-09-29 | B21: Tue | C21: 2 | D21: reset | E21: mobility | F21: Mobility + lower-leg prehab | G21: 15 min | P21: Ankle dorsiflexion (knee-to-wall), calf and soleus stretch, hip flexors, thoracic rotation, and 3 × 20 tibialis raises. Ten minutes of this beats an hour once a month.
A22: 2026-09-30 | B22: Wed | C22: 2 | D22: reset | E22: swim | F22: Swim — speed + bilateral breathing | G22: 1,900 yd · 42–56 min | H22: 1900 | P22: Warm-up 300. Drill 400 focused on breathing: 3/5/3 pattern, 6-1-6 both sides. Main 16 × 50 on 1:10, odd ones aerobic and even ones fast. Then 4 × 50 breaststroke working the pull-breathe-kick-glide timing. Cool-down 200.
A23: 2026-09-30 | B23: Wed | C23: 2 | D23: reset | E23: bike | F23: Spin bike — 20 min FTP test | G23: 50 min | P23: Keiser M3i. 15 min warm-up with 3 × 1 min builds, then 20 min all-out at an even effort, then 10 min easy. FTP ≈ 95% of your 20 min average watts. Use the same bike as Sep 23 so the comparison means something. Pacing is the whole test: go out too hard and you fade, and the number comes out low. Ignore the level — on a Keiser the level only sets resistance, and the same level gives very different watts at different cadences, so it is never a target. Result, run Oct 1: 205 W for 10 min, 195 W for 5, 180 W for the last 5, averaging 196 W, so FTP = 186 W and 2.56 W/kg. That is inside the 180–200 W predicted from the Sep 23 ride, so estimate and test agree. The 12% fade is a pacing signature rather than the nutrition and rest you suspected — those usually lower the whole curve or cause a late cliff, not a steady slide from minute ten — which means 186 W is, if anything, slightly conservative. Every bike target in this block now reads in watts off that number; it gets re-cut at the Week 8 retest. Note also that the session ran 94 min rather than the 50 prescribed, so the Thursday was a far bigger day than designed — fine once, worth not repeating on a test day.
A24: 2026-10-01 | B24: Thu | C24: 2 | D24: reset | E24: strength | F24: Strength B — Bulgarian split squat + hips and core | G24: 45–55 min | P24: First Strength B. Bulgarian split squats on the Smith machine — find a load where rep 8 is hard but clean. Copenhagen planks will humble you; start on the short lever (knee on bench).
A25: 2026-10-01 | B25: Thu | C25: 2 | D25: reset | E25: mobility | F25: Mobility + lower-leg prehab | G25: 15 min | P25: Ankle dorsiflexion (knee-to-wall), calf and soleus stretch, hip flexors, thoracic rotation, and 3 × 20 tibialis raises. Ten minutes of this beats an hour once a month.
A26: 2026-10-02 | B26: Fri | C26: 2 | D26: reset | E26: swim | F26: Swim — long aerobic 1,200 | G26: 2,200 yd · 49–65 min | H26: 2200 | P26: Warm-up 300. Main: 1,200 continuous aerobic, then 4 × 100 at CSS on 2:20. Cool-down 300. Result, Oct 2: 2,220 yd in 46:42 at 2:01/100 with an average heart rate of 125 — the top of the aerobic band at a genuinely calm heart rate, which is exactly what this session is for. The left-breathing instruction that was here is withdrawn. It asked you to breathe left for the first 50 of every 200 inside the continuous swim and the hips and feet sank immediately, which is a sequencing error in the plan rather than a failure on your part: you cannot learn a balance skill inside a 1,200 where the effort is constant and there is no chance to reset. What sinks you is almost certainly the lead arm pressing down to lever your face up, plus the kick stopping during the breath, plus air hunger from an incomplete exhale making you lift the head instead of rotating. All three are fixed in drills, not in continuous swimming. The left-side ladder now runs side kick, side kick + breathe, left-breathing single-arm, then easy 50s with rest — and continuous swims do not ask for it again until Week 10.
A27: 2026-10-02 | B27: Fri | C27: 2 | D27: reset | E27: strength | F27: Chest and shoulders | G27: 45–55 min | P27: First upper day of the block. Your shoulders do a lot of internal rotation in the water, so the point here is the opposite — press, then row and pull apart to balance it. Keep the overhead press light and strict; if the shoulder pinches at the top, switch to a landmine press.
A28: 2026-10-03 | B28: Sat | C28: 2 | D28: reset | E28: cardio | F28: Stairmaster + 10 lb pack | G28: 40 min | P28: Steady climb, 40 min, 10 lb in the pack. This is Rainier maintenance, not a workout — keep HR under 150 and let the legs do slow steady work.
A29: 2026-10-03 | B29: Sat | C29: 2 | D29: reset | E29: swim | F29: Technique swim (short) | G29: 900 yd · 20–26 min | H29: 900 | P29: About 900 yd total, all easy. No clock, no main set. Snorkel and fins for the first half — catch-up, fingertip drag and front scull, rotating through them — then easy 50s holding the feel. This session exists to raise frequency and keep the stroke fresh — leave the pool fresher than you arrived.
A30: 2026-10-04 | B30: Sun | C30: 2 | D30: reset | E30: bike | F30: Endurance ride — Z2 | G30: 60 min | P30: Outdoors while the weather allows. 130–145 bpm and 104–140 W, steady. First ride off the new FTP — the band is narrower than it looks, and Sep 23 proves it: 130–150 W felt easy and still spent half its time above Z2.
A31: 2026-10-04 | B31: Sun | C31: 2 | D31: reset | E31: mobility | F31: Mobility + lower-leg prehab | G31: 20 min | P31: Mobility plus foot intrinsics. Check knee-to-wall and log the number.
A32: 2026-10-05 | B32: Mon | C32: 3 | D32: reset | E32: swim | F32: Swim — threshold 5 × 200 | G32: 2,100 yd · 47–62 min | H32: 2100 | P32: Warm-up 400. Drill 400 as 8 × 50, each drill twice: single-arm / front kick / catch-up / 6-1-6. Fins throughout; snorkel off for 6-1-6. Main: 5 × 200 at CSS on 4:25 (about 39 s rest). Cool-down 300. Longer reps at the same pace — this is where the sprint-to-distance gap actually closes.
A33: 2026-10-05 | B33: Mon | C33: 3 | D33: reset | E33: strength | F33: Strength A — RDL + posterior chain | G33: 45–55 min | P33: Progress the RDL. Log the weight; you want to see this number move across the block.
A34: 2026-10-06 | B34: Tue | C34: 3 | D34: reset | E34: run | F34: Easy run — 4 km | G34: 28–32 min | I34: 4 | P34: ORTHOTIC GATE: if they have not arrived, skip this and run only on Thursday. If they have, this is your first run in them — keep it short deliberately. New orthotics change how your foot loads, and calf soreness in the first two weeks is expected.
A35: 2026-10-06 | B35: Tue | C35: 3 | D35: reset | E35: mobility | F35: Mobility + lower-leg prehab | G35: 15 min | P35: Ankle dorsiflexion (knee-to-wall), calf and soleus stretch, hip flexors, thoracic rotation, and 3 × 20 tibialis raises. Ten minutes of this beats an hour once a month.
A36: 2026-10-07 | B36: Wed | C36: 3 | D36: reset | E36: swim | F36: Swim — speed 20 × 50 | G36: 2,200 yd · 49–65 min | H36: 2200 | P36: Warm-up 300. Drill 400 as 8 × 50, the left-side ladder in order: side kick + breathe (left) ×2 / 6-1-6 ×2 / left-breathing single-arm ×2 / 3/5/3 breathing ×2. Fins throughout and no snorkel at all today — every drill in this block is about getting air, which is exactly what a snorkel removes. Work the ladder in sequence and do not move up until the current rung is calm: if the hips drop on the side kick, stay there. Main: 20 × 50 on 1:10, alternating aerobic and fast. Then 4 × 50 breaststroke. Cool-down 300. The fast ones should be 1:38–1:48/100 pace, not sprints.
A37: 2026-10-07 | B37: Wed | C37: 3 | D37: reset | E37: bike | F37: Spin bike — sweet spot 3 × 8 min | G37: 50 min | P37: 3 × 8 min at 164–173 W (88–93% of your 186 W FTP) with 4 min easy between. Cadence 85–95. First structured bike session of the block — hold the bottom of the band on the first interval, because the last one is the one that counts.
A38: 2026-10-08 | B38: Thu | C38: 3 | D38: reset | E38: run | F38: Easy run — 5 km | G38: 32–36 min | I38: 5 | P38: Track or soft trail, easy throughout. This is the week's long run even though it is short — that is the point.
A39: 2026-10-08 | B39: Thu | C39: 3 | D39: reset | E39: strength | F39: Strength B — Bulgarian split squat + hips and core | G39: 45–55 min | P39: Bulgarian split squats slightly heavier. If the shins are talking after two runs this week, drop the step-ups and add a third set of soleus raises instead.
A40: 2026-10-09 | B40: Fri | C40: 3 | D40: reset | E40: swim | F40: Swim — long aerobic 1,400 | G40: 2,400 yd · 53–71 min | H40: 2400 | P40: Warm-up 300. Main: 1,400 continuous, then 4 × 100 at CSS on 2:20. Cool-down 300. Compare the HR drift on the 1,400 to Week 1's 1,000 — the target is a flatter curve, not a faster swim.
A41: 2026-10-09 | B41: Fri | C41: 3 | D41: reset | E41: strength | F41: Back and biceps | G41: 45–55 min | P41: Upper day, pulling half of the rotation. Everything here is a row or a pull-down, which is the same pattern your catch uses — train it heavy and slow and the stroke gets a stronger anchor. Pull-ups to failure at the end, however many that is.
...

Sheet Week Summary
A1: Weekly rollup
A2: Every number here is a live formula over the Log sheet. Nothing to type.
A4: Wk | B4: Starts | C4: Theme | D4: Swim plan (yd) | E4: Swim actual | F4: Swim Δ | G4: 6,000 floor | H4: Run plan (km) | I4: Run actual | J4: Run Δ | K4: Sessions | L4: Done | M4: % done
A5: 1 | B5: 2026-09-21 | C5: Measure everything | D5: =SUMIFS(Log!$H$5:$H$400,Log!$C$5:$C$400,$A5) | E5: =SUMIFS(Log!$K$5:$K$400,Log!$C$5:$C$400,$A5) | F5: =IF(E5=0,"",E5-D5) | G5: =IF(E5=0,"–",IF(E5>=6000,"OK","UNDER")) | H5: =SUMIFS(Log!$I$5:$I$400,Log!$C$5:$C$400,$A5) | I5: =SUMIFS(Log!$L$5:$L$400,Log!$C$5:$C$400,$A5) | J5: =IF(I5=0,"",I5-H5) | K5: =COUNTIFS(Log!$C$5:$C$400,$A5) | L5: =COUNTIFS(Log!$C$5:$C$400,$A5,Log!$J$5:$J$400,"Y") | M5: =IFERROR(L5/K5,0)
A6: 2 | B6: 2026-09-28 | C6: Learn the send-off | D6: =SUMIFS(Log!$H$5:$H$400,Log!$C$5:$C$400,$A6) | E6: =SUMIFS(Log!$K$5:$K$400,Log!$C$5:$C$400,$A6) | F6: =IF(E6=0,"",E6-D6) | G6: =IF(E6=0,"–",IF(E6>=6000,"OK","UNDER")) | H6: =SUMIFS(Log!$I$5:$I$400,Log!$C$5:$C$400,$A6) | I6: =SUMIFS(Log!$L$5:$L$400,Log!$C$5:$C$400,$A6) | J6: =IF(I6=0,"",I6-H6) | K6: =COUNTIFS(Log!$C$5:$C$400,$A6) | L6: =COUNTIFS(Log!$C$5:$C$400,$A6,Log!$J$5:$J$400,"Y") | M6: =IFERROR(L6/K6,0)
A7: 3 | B7: 2026-10-05 | C7: Second run — if the orthotics are in | D7: =SUMIFS(Log!$H$5:$H$400,Log!$C$5:$C$400,$A7) | E7: =SUMIFS(Log!$K$5:$K$400,Log!$C$5:$C$400,$A7) | F7: =IF(E7=0,"",E7-D7) | G7: =IF(E7=0,"–",IF(E7>=6000,"OK","UNDER")) | H7: =SUMIFS(Log!$I$5:$I$400,Log!$C$5:$C$400,$A7) | I7: =SUMIFS(Log!$L$5:$L$400,Log!$C$5:$C$400,$A7) | J7: =IF(I7=0,"",I7-H7) | K7: =COUNTIFS(Log!$C$5:$C$400,$A7) | L7: =COUNTIFS(Log!$C$5:$C$400,$A7,Log!$J$5:$J$400,"Y") | M7: =IFERROR(L7/K7,0)
A8: 4 | B8: 2026-10-12 | C8: Build I opens | D8: =SUMIFS(Log!$H$5:$H$400,Log!$C$5:$C$400,$A8) | E8: =SUMIFS(Log!$K$5:$K$400,Log!$C$5:$C$400,$A8) | F8: =IF(E8=0,"",E8-D8) | G8: =IF(E8=0,"–",IF(E8>=6000,"OK","UNDER")) | H8: =SUMIFS(Log!$I$5:$I$400,Log!$C$5:$C$400,$A8) | I8: =SUMIFS(Log!$L$5:$L$400,Log!$C$5:$C$400,$A8) | J8: =IF(I8=0,"",I8-H8) | K8: =COUNTIFS(Log!$C$5:$C$400,$A8) | L8: =COUNTIFS(Log!$C$5:$C$400,$A8,Log!$J$5:$J$400,"Y") | M8: =IFERROR(L8/K8,0)
A9: 5 | B9: 2026-10-19 | C9: Third run, paddles in | D9: =SUMIFS(Log!$H$5:$H$400,Log!$C$5:$C$400,$A9) | E9: =SUMIFS(Log!$K$5:$K$400,Log!$C$5:$C$400,$A9) | F9: =IF(E9=0,"",E9-D9) | G9: =IF(E9=0,"–",IF(E9>=6000,"OK","UNDER")) | H9: =SUMIFS(Log!$I$5:$I$400,Log!$C$5:$C$400,$A9) | I9: =SUMIFS(Log!$L$5:$L$400,Log!$C$5:$C$400,$A9) | J9: =IF(I9=0,"",I9-H9) | K9: =COUNTIFS(Log!$C$5:$C$400,$A9) | L9: =COUNTIFS(Log!$C$5:$C$400,$A9,Log!$J$5:$J$400,"Y") | M9: =IFERROR(L9/K9,0)
A10: 6 | B10: 2026-10-26 | C10: New York — city week | D10: =SUMIFS(Log!$H$5:$H$400,Log!$C$5:$C$400,$A10) | E10: =SUMIFS(Log!$K$5:$K$400,Log!$C$5:$C$400,$A10) | F10: =IF(E10=0,"",E10-D10) | G10: =IF(E10=0,"–",IF(E10>=6000,"OK","UNDER")) | H10: =SUMIFS(Log!$I$5:$I$400,Log!$C$5:$C$400,$A10) | I10: =SUMIFS(Log!$L$5:$L$400,Log!$C$5:$C$400,$A10) | J10: =IF(I10=0,"",I10-H10) | K10: =COUNTIFS(Log!$C$5:$C$400,$A10) | L10: =COUNTIFS(Log!$C$5:$C$400,$A10,Log!$J$5:$J$400,"Y") | M10: =IFERROR(L10/K10,0)
A11: 7 | B11: 2026-11-02 | C11: Back-loaded return | D11: =SUMIFS(Log!$H$5:$H$400,Log!$C$5:$C$400,$A11) | E11: =SUMIFS(Log!$K$5:$K$400,Log!$C$5:$C$400,$A11) | F11: =IF(E11=0,"",E11-D11) | G11: =IF(E11=0,"–",IF(E11>=6000,"OK","UNDER")) | H11: =SUMIFS(Log!$I$5:$I$400,Log!$C$5:$C$400,$A11) | I11: =SUMIFS(Log!$L$5:$L$400,Log!$C$5:$C$400,$A11) | J11: =IF(I11=0,"",I11-H11) | K11: =COUNTIFS(Log!$C$5:$C$400,$A11) | L11: =COUNTIFS(Log!$C$5:$C$400,$A11,Log!$J$5:$J$400,"Y") | M11: =IFERROR(L11/K11,0)
A12: 8 | B12: 2026-11-09 | C12: Retest + race distance | D12: =SUMIFS(Log!$H$5:$H$400,Log!$C$5:$C$400,$A12) | E12: =SUMIFS(Log!$K$5:$K$400,Log!$C$5:$C$400,$A12) | F12: =IF(E12=0,"",E12-D12) | G12: =IF(E12=0,"–",IF(E12>=6000,"OK","UNDER")) | H12: =SUMIFS(Log!$I$5:$I$400,Log!$C$5:$C$400,$A12) | I12: =SUMIFS(Log!$L$5:$L$400,Log!$C$5:$C$400,$A12) | J12: =IF(I12=0,"",I12-H12) | K12: =COUNTIFS(Log!$C$5:$C$400,$A12) | L12: =COUNTIFS(Log!$C$5:$C$400,$A12,Log!$J$5:$J$400,"Y") | M12: =IFERROR(L12/K12,0)
A13: 9 | B13: 2026-11-16 | C13: Peak week | D13: =SUMIFS(Log!$H$5:$H$400,Log!$C$5:$C$400,$A13) | E13: =SUMIFS(Log!$K$5:$K$400,Log!$C$5:$C$400,$A13) | F13: =IF(E13=0,"",E13-D13) | G13: =IF(E13=0,"–",IF(E13>=6000,"OK","UNDER")) | H13: =SUMIFS(Log!$I$5:$I$400,Log!$C$5:$C$400,$A13) | I13: =SUMIFS(Log!$L$5:$L$400,Log!$C$5:$C$400,$A13) | J13: =IF(I13=0,"",I13-H13) | K13: =COUNTIFS(Log!$C$5:$C$400,$A13) | L13: =COUNTIFS(Log!$C$5:$C$400,$A13,Log!$J$5:$J$400,"Y") | M13: =IFERROR(L13/K13,0)
A14: 10 | B14: 2026-11-23 | C14: Edmonton — absorb | D14: =SUMIFS(Log!$H$5:$H$400,Log!$C$5:$C$400,$A14) | E14: =SUMIFS(Log!$K$5:$K$400,Log!$C$5:$C$400,$A14) | F14: =IF(E14=0,"",E14-D14) | G14: =IF(E14=0,"–",IF(E14>=6000,"OK","UNDER")) | H14: =SUMIFS(Log!$I$5:$I$400,Log!$C$5:$C$400,$A14) | I14: =SUMIFS(Log!$L$5:$L$400,Log!$C$5:$C$400,$A14) | J14: =IF(I14=0,"",I14-H14) | K14: =COUNTIFS(Log!$C$5:$C$400,$A14) | L14: =COUNTIFS(Log!$C$5:$C$400,$A14,Log!$J$5:$J$400,"Y") | M14: =IFERROR(L14/K14,0)
A15: 11 | B15: 2026-11-30 | C15: Race week — run-only taper | D15: =SUMIFS(Log!$H$5:$H$400,Log!$C$5:$C$400,$A15) | E15: =SUMIFS(Log!$K$5:$K$400,Log!$C$5:$C$400,$A15) | F15: =IF(E15=0,"",E15-D15) | G15: =IF(E15=0,"–",IF(E15>=6000,"OK","UNDER")) | H15: =SUMIFS(Log!$I$5:$I$400,Log!$C$5:$C$400,$A15) | I15: =SUMIFS(Log!$L$5:$L$400,Log!$C$5:$C$400,$A15) | J15: =IF(I15=0,"",I15-H15) | K15: =COUNTIFS(Log!$C$5:$C$400,$A15) | L15: =COUNTIFS(Log!$C$5:$C$400,$A15,Log!$J$5:$J$400,"Y") | M15: =IFERROR(L15/K15,0)
A16: 12 | B16: 2026-12-07 | C16: Florida — front-load, then travel light | D16: =SUMIFS(Log!$H$5:$H$400,Log!$C$5:$C$400,$A16) | E16: =SUMIFS(Log!$K$5:$K$400,Log!$C$5:$C$400,$A16) | F16: =IF(E16=0,"",E16-D16) | G16: =IF(E16=0,"–",IF(E16>=6000,"OK","UNDER")) | H16: =SUMIFS(Log!$I$5:$I$400,Log!$C$5:$C$400,$A16) | I16: =SUMIFS(Log!$L$5:$L$400,Log!$C$5:$C$400,$A16) | J16: =IF(I16=0,"",I16-H16) | K16: =COUNTIFS(Log!$C$5:$C$400,$A16) | L16: =COUNTIFS(Log!$C$5:$C$400,$A16,Log!$J$5:$J$400,"Y") | M16: =IFERROR(L16/K16,0)
... A19: 15 | B19: 2026-12-28 | C19: Close the block | D19: =SUMIFS(Log!$H$5:$H$400,Log!$C$5:$C$400,$A19) | E19: =SUMIFS(Log!$K$5:$K$400,Log!$C$5:$C$400,$A19) | F19: =IF(E19=0,"",E19-D19) | G19: =IF(E19=0,"–",IF(E19>=6000,"OK","UNDER")) | H19: =SUMIFS(Log!$I$5:$I$400,Log!$C$5:$C$400,$A19) | I19: =SUMIFS(Log!$L$5:$L$400,Log!$C$5:$C$400,$A19) | J19: =IF(I19=0,"",I19-H19) | K19: =COUNTIFS(Log!$C$5:$C$400,$A19) | L19: =COUNTIFS(Log!$C$5:$C$400,$A19,Log!$J$5:$J$400,"Y") | M19: =IFERROR(L19/K19,0)
A20: All | C20: Block total | D20: =SUM(D5:D19) | E20: =SUM(E5:E19) | H20: =SUM(H5:H19) | I20: =SUM(I5:I19) | K20: =SUM(K5:K19) | L20: =SUM(L5:L19) | M20: =IFERROR(L20/K20,0)

Sheet Swim
A1: Swim — the engine of this block
A2: CSS drives every send-off. Retest Sep 21, Nov 9, Dec 28 and update the yellow cells.
A4: CSS test log
A5: Date | B5: 400 yd time | C5: 200 yd time | D5: CSS /100 yd (sec) | E5: CSS as m:ss | F5: Notes
A6: 2026-09-21 | B6: 0.0049305556 | C6: 0.0023148148 | D6: =IF(OR(B6="",C6=""),"",ROUND((B6-C6)*86400/2,1)) | E6: =IF(D6="","",INT(D6/60)&":"&TEXT(MOD(D6,60),"00")) | F6: First CSS test. The 400/200 ratio is 2.13, inside the normal 2.10–2.20 band, so the number is internally consistent. What the ratio cannot detect is both swims being submaximal together, and that now looks like what happened: on Oct 5 the warm-up 400 came in at 7:07.5 and the 5 × 200 that followed averaged 1:47.6/100 without fading. Treat 1:53 as a soft floor rather than a true threshold until Nov 9 re-measures it.
A7: 2026-11-09 | D7: =IF(OR(B7="",C7=""),"",ROUND((B7-C7)*86400/2,1)) | E7: =IF(D7="","",INT(D7/60)&":"&TEXT(MOD(D7,60),"00"))
A8: 2026-12-28 | D8: =IF(OR(B8="",C8=""),"",ROUND((B8-C8)*86400/2,1)) | E8: =IF(D8="","",INT(D8/60)&":"&TEXT(MOD(D8,60),"00"))
A9: Enter times as m:ss (e.g. 7:40). CSS = (T400 − T200) ÷ 2, in seconds per 100 yd. Yellow rows are retests still to come — fill the two times and CSS computes itself.
A11: Week 8 retest target — 2026-11-09
A12: Scenario | B12: 400 yd | C12: 200 yd | D12: CSS /100 yd
A13: Sep 21 baseline | B13: 7:06 | C13: 3:20 | D13: 1:53
A14: Floor — an honest test, no fitness gained | B14: 7:00 | C14: 3:18 | D14: 1:51
A15: Good — the number to aim at | B15: 6:52 | C15: 3:16 | D15: 1:48
A16: Strong | B16: 6:44 | C16: 3:12 | D16: 1:46
A17: Two execution notes, both learned the hard way. First, warm up genuinely easy — 2:08–2:13/100, not the 1:45s of the last two sessions — because a 400 TT off a hard warm-up is just a second hard swim. Second, pace the 400 off the clock and not off feel: 1:42 for the first 100, 1:43s through the middle, empty the tank on the last 50. Then 5 min full rest before the 200. Run the protocol identically or the comparison means nothing.
A19: Pace zones (recalculate off your measured CSS)
A20: Zone | B20: Target | C20: Cue
A21: Easy / recovery | B21: 2:08–2:13 | C21: CSS + 15–20 s. Conversational. Warm-up, cool-down, and the technique swim.
A22: Aerobic (Z2) | B22: 2:01–2:05 | C22: CSS + 8–12 s. What a long continuous swim should feel like. Nose-breathing calm.
A23: CSS / threshold | B23: 1:51–1:55 | C23: Your tested 1:53, give or take 2 s. The engine of this block — comfortably hard, repeatable for 20–40 min of work.
A24: Fast (VO2) | B24: 1:45–1:48 | C24: CSS −5 to −8 s. 50s and short 100s, still with a clean catch and a long stroke.
A25: Sprint | B25: 1:35–1:40 | C25: 25s and the last 50 of a set. 1:40 is your 200 TT pace — anything quicker is a genuine sprint, so use it sparingly.
A27: Send-offs
A28: Set | B28: Send-off | C28: Rest
A29: 100 aerobic | B29: 2:30 | C29: ~27 s
A30: 100 threshold (CSS) | B30: 2:15 | C30: ~22 s
A31: 100 fast | B31: 2:30 | C31: ~43 s
A32: 50 aerobic | B32: 1:15 | C32: ~13 s
A33: 50 threshold (CSS) | B33: 1:05 | C33: ~8 s
A34: 50 fast | B34: 1:15 | C34: ~22 s
A35: 200 threshold (CSS) | B35: 4:25 | C35: ~39 s
A37: Drill progression
A38: Phase | B38: Title | C38: Focus | D38: Drills
A39: Weeks 1–3 | B39: Body position + the send-off habit | C39: Get the new gear working and stop the sessions from being rest-dominated. Snorkel removes breathing as a variable so body and head position can actually be felt. | D39: Snorkel + fins, 6 × 50: flutter kick on front, eyes down, hips high. · 6-1-6 with fins, 4 × 50 per side: six kicks on the side, one stroke, six on the other. · Catch-up, 4 × 50: patient lead arm, long body line, no crossover. · Fingertip drag, 4 × 50: relaxed recovery, high elbow, unhurried rotation. · Breathe-3 on easy 50s only — warm-up and cool-down, never inside a hard set. · Left-side ladder starts here: side kick (left) until stable, then side kick + breathe.
A40: Weeks 4–7 | B40: Catch + symmetry | C40: Build an earlier, higher-elbow catch and start balancing the stroke. Paddles arrive in Week 5 and stay capped. | D40: Front scull, 3 × 50 with snorkel: forearm vertical, pressure back not down. · Single-arm freestyle, 4 × 50 per side: the weak (left-breathing) side gets the extra 50. · Left-breathing single-arm, 4 × 50 with fins: right arm as a rail, breathe left every stroke. · Closed-fist, 4 × 50, then 50 normal — the contrast teaches the forearm to grip water. · 3/5/3 breathing pattern through warm-ups: three strokes, five strokes, three. · Small paddles + pull buoy, max 400 yd: hold the catch, stop if the shoulder complains. · Breaststroke timing, 4 × 50: pull, breathe, kick, glide — one thing at a time.
A41: Weeks 8–15 | B41: Hold form under fatigue | C41: Technique that survives a hard set is the only technique that counts. Stroke count and SWOLF become the feedback loop since there is no coach on deck. | D41: Stroke-count ladder, 4 × 50: hold a fixed count per length, then drop it by one. · Descending 100s at a fixed stroke count — get faster without adding strokes. · Breathe-3 on easy 50s with rest, and only inside continuous swimming once the left breath survives those. · Sighting, 6 × 50: eyes just above the water every 6–8 strokes, ahead of open water next year. · Breaststroke 200 continuous — an honest second stroke, not a novelty. · Self-check every Monday: log the 100 that felt best and its stroke count.
A43: Before every swim
A44: Checklist
A45: Fins and center-mount snorkel in the bag from Week 1; small paddles bought before Week 5, which is when they enter.
A46: Know your CSS number and carry the send-off table on your phone.
...

Sheet Drills
A1: Swim drill library
A2: Every drill the sessions refer to by name. Gear is not decoration: a center-mount snorkel sits on the centreline of your face, so it floods the moment you rotate onto your side — side-lying drills, and anything whose point is getting air, are fins-only.
A4: Drills
A5: Drill | B5: Gear | C5: What you do | D5: Feel for | E5: Watch for | F5: Why it is in the plan
A6: Front kick | B6: Snorkel + fins | C6: Kick on your front, arms extended in front or flat at your sides, face down, eyes straight at the bottom. | D6: Hips high and the kick coming from the hip, not the knee — small, fast, ankles loose. Your head is the rudder: lift it and the hips sink. | E6: Bending at the knee like pedalling a bike, and kicking big and slow because it feels more powerful. It isn't. | F6: This is the drill the snorkel exists for. With breathing removed you can actually feel where your hips are sitting.
A7: Side kick | B7: Fins only — no snorkel | C7: Kick on one side, lead arm extended, top arm resting along your hip, body rotated a full 90°, head in line with your spine. | D7: Balance. You should be able to hold it without sculling to stay up. Press the lead armpit lightly down and stack the top hip directly over the bottom one. | E7: Rolling only 45° and calling it a side. Also craning your neck to look forward — keep the head in line and breathe by rolling slightly. | F7: At a true 90° a center-mount snorkel is lying sideways and will flood, which is why this one is fins-only.
A8: Side kick + breathe | B8: Fins only — no snorkel | C8: Side-kick on your weak (left) side, lead arm extended as a rail. Stay there and take relaxed breaths by rolling your face just clear of the water, then rolling it back down. No stroke at all — just kick, breathe, kick. | D8: That you can get air on the left without anything else changing. The lower goggle stays in the water and the head rests on the lead shoulder rather than lifting off it. | E8: Pressing down on the lead arm to lever the face up. That is the exact move that drops your hips — the lead arm is a rail, not a lever. Also stopping the kick to breathe. | F8: This is the rung between rotating well and breathing well. Side kick teaches balance with no air; breathe-3 asks for balance and air at full stroke rate. This one asks for air while the balance is already solved, which is why it is the drill to start with when the left side sinks.
A9: Left-breathing single-arm | B9: Fins — no snorkel | C9: Right arm stays extended in front as a rail. Left arm does every stroke, and you breathe to the left on every one. | D9: A breath that arrives because the body rotated, not because the neck turned. The extended right arm gives you something to balance against while the timing is still new. | E9: Pushing down on the extended right arm each time you go for air. Keep it patient and slightly deep — it holds a line, it does not hold you up. | F9: Bridges the gap between side kick and real swimming. You get the left breath many times per length with the support still present, which is the repetition the pattern needs before it survives a full stroke.
A10: 6-1-6 | B10: Fins only — no snorkel | C10: From the side-kick position: six kicks on your left side, one full stroke, six kicks on your right, repeat. | D10: The hips drive the rotation and the arm just goes along with it. The single stroke should land you cleanly stacked on the other side, not halfway. | E10: Yanking yourself over with the arm, cutting the six kicks short, and quietly only rotating well to the strong side. | F10: Your rotation and your breathing share the same movement. This is the drill that fixes the left side — expect it to feel clumsy, that's the information.
A11: Catch-up | B11: Snorkel + fins | C11: Full freestyle, but the lead arm stays extended out front until the recovering hand touches it, then they swap. | D11: A long, patient front end — one arm is always extended. This is front-quadrant timing. | E11: Letting the lead arm drop early, and crossing the centreline as the hand comes in to touch. | F11: Forces extension and stops the stroke from turning into a windmill where both arms are pulling at once.
A12: Fingertip drag | B12: Fins; snorkel optional | C12: Normal freestyle, but your fingertips drag along the surface through the entire recovery. | D12: A high elbow and a heavy, relaxed hand. It should feel unhurried — the recovery is the rest part of the stroke. | E12: Swinging the arm wide around the side instead of leading with the elbow. | F12: You cannot drag your fingertips without a high elbow, so the drill enforces the shape rather than asking you to remember it.
A13: Single-arm freestyle | B13: Snorkel + fins | C13: One arm does all the work. The other stays extended in front (harder, better balance) or rests at your side (more rotation). | D13: Exactly where in the pull you lose pressure. With only one arm there is nowhere to hide a weak catch. | E13: Rushing the front of the stroke, and forgetting to rotate because only one side is moving. | F13: The snorkel matters here — breathing during single-arm is awkward enough that it wrecks the drill.
A14: Front scull | B14: Snorkel + pull buoy or fins | C14: Face down, forearms vertical, hands sweeping in and out in front of your head in small continuous figure-eights. | D14: Pressure pushing back toward your feet, not down toward the bottom. This is what 'grip on the water' actually means. | E14: Pressing down, which lifts your chest, drops your legs and stalls you. | F14: The catch is the hardest thing in freestyle to feel. Sculling slows it down enough to notice.
A15: Closed-fist | B15: None | C15: Swim with your fists closed, then open the hands for the following length. | D15: With no hand you are forced onto the forearm. The lesson is the contrast when the hand comes back. | E15: Going easy. Swim it at normal effort or there is no contrast to feel. | F15: Teaches the forearm to do its share instead of the hand doing everything.
A16: Breathe-3 | B16: None | C16: Breathe every third stroke, which alternates the side you breathe to. | D16: Even. If one side feels like a different stroke, that is the asymmetry you are here to remove. | E16: Forcing it inside a hard set or a long continuous swim. Tried in the Oct 2 long swim and the hips and feet sank immediately — this drill is the top of the ladder, not the way onto it. Keep it to short easy 50s with rest until the left breath is stable there. | F16: You currently breathe right every two strokes. This is the single habit that unlocks the balanced stroke — but it is the last rung, reached through side kick, side kick + breathe and left-breathing single-arm, not jumped to.
... A18: Breaststroke timing | B18: None — no snorkel | C18: Pull, breathe, kick, glide — deliberately one thing at a time, with a pause on the glide. | D18: The glide. Breaststroke is the one stroke where doing less, later, is faster. | E18: Rushing into the next pull before the glide has happened, so you fight your own kick. | F18: Your second stroke should be honest, not a novelty — and the breath is part of the timing, so no snorkel.
A19: Stroke-count ladder | B19: None | C19: Hold a fixed number of strokes per 25, then take one stroke off each round. | D19: Distance per stroke. Getting faster without adding strokes is the whole game. | E19: Gliding to hit the number. You want a better catch, not a longer pause.
A20: Sighting | B20: None — no snorkel | C20: Lift the eyes just above the surface every six to eight strokes, then straight back down into the breath. | D20: Quick alligator eyes. The head barely moves and the rhythm does not break. | E20: Lifting the whole head, which sinks the hips and costs more than the look is worth. | F20: Free speed in open water next year, and cheap to build now.
A21: Paddles + pull buoy | B21: Small paddles + pull buoy | C21: Pull sets only, capped at roughly 400 yd per session, small paddles only. | D21: The catch holding pressure for longer. If you feel it in the front of the shoulder, stop. | E21: Big paddles, or using them to swim faster rather than to hold a better catch. | F21: Three months of swimming is a young training age for a shoulder. Paddles are the first thing to drop if anything hurts above 2/10.

Sheet Bike
A1: Bike — FTP and the winter power block
A2: FTP is the bike's CSS: the highest power you could hold for about an hour, taken as 95% of a 20 min all-out average. Every interval in the plan is a percentage of it, so the zone table is formula-driven — update the test log and the zones re-cut themselves.
A4: Body weight (kg) | B4: 72.6 | C4: Key assumption — every W/kg below divides by this cell. Source: plan.js blockMeta.bodyWeightKg (COROS profile). Update it if your weight moves.
A6: FTP test log
A7: Date | B7: 20 min avg (W) | C7: FTP (W) | D7: W/kg | E7: Notes
A8: 2026-10-01 | B8: 196 | C8: =IF(B8="","",ROUND(B8*0.95,0)) | D8: =IF(C8="","",ROUND(C8/$B$4,2)) | E8: Split 205 W for 10 min, 195 W for 5 min, 180 W for the last 5 — a 12% fade. That shape is the signature of opening above threshold rather than of nutrition or sleep, which tend to lower the whole curve or cause a late cliff instead of a steady slide from minute ten. The plan said to open at 195 and the opening was 205. The cost is small — an even ride was probably worth 190-odd — so 186 W is the honest number to train against, and a mild underestimate rather than an optimistic one. It also lands inside the 180–200 W predicted from the Sep 23 Z2 ride, which means the estimate and the test agree.
A9: 2026-11-11 | C9: =IF(B9="","",ROUND(B9*0.95,0)) | D9: =IF(C9="","",ROUND(C9/$B$4,2))
A10: Type the 20 min average into the blue column; FTP and W/kg are formulas. These are Keiser console watts — estimated from resistance and cadence, not measured by a strain gauge. Consistent against themselves, but not transferable to another bike or a real power meter. Retest on the same equipment or not at all.
A12: Current FTP (W) | B12: =IFERROR(LOOKUP(2,1/($C$8:$C$9<>""),$C$8:$C$9),0) | C12: Last completed test. The zone table below cuts off this cell.
A14: Power zones (live — cut from current FTP)
A15: Zone | B15: % of FTP | C15: Watts | D15: Cue
A16: Recovery | B16: < 55% | C16: ="< "&TEXT(ROUND($B$12*0.55,0),"0")&" W" | D16: Spinning between intervals. Should feel like nothing.
A17: Endurance (Z2) | B17: 56–75% | C17: =TEXT(ROUND($B$12*0.56,0),"0")&"–"&TEXT(ROUND($B$12*0.75,0),"0")&" W" | D17: Every easy ride. Note that the Sep 23 spin ran 130–150 W, so its top half was already tempo — this is the band it should have been in.
A18: Tempo | B18: 76–90% | C18: =TEXT(ROUND($B$12*0.76,0),"0")&"–"&TEXT(ROUND($B$12*0.9,0),"0")&" W" | D18: Steady, breathy, sustainable. Rarely prescribed on its own here — it mostly shows up as the back half of a long ride.
A19: Sweet spot | B19: 88–93% | C19: =TEXT(ROUND($B$12*0.88,0),"0")&"–"&TEXT(ROUND($B$12*0.93,0),"0")&" W" | D19: The workhorse of this block. Hard enough to move FTP, cheap enough in recovery that it does not steal from the swim and run days.
A20: Threshold | B20: 95–105% | C20: =TEXT(ROUND($B$12*0.95,0),"0")&"–"&TEXT(ROUND($B$12*1.05,0),"0")&" W" | D20: Around and just above FTP, 155–165 bpm. The 8 min repeats live here.
A21: VO2max | B21: 106–120% | C21: =TEXT(ROUND($B$12*1.06,0),"0")&"–"&TEXT(ROUND($B$12*1.2,0),"0")&" W" | D21: Short, sharp, sparingly. Raises the ceiling that sweet spot sits under.
A22: 70.3 race pace | B22: 70–75% | C22: =TEXT(ROUND($B$12*0.7,0),"0")&"–"&TEXT(ROUND($B$12*0.75,0),"0")&" W" | D22: What today's FTP would let you ride for 56 miles while still running off it. Worth knowing because it is the gap: see the target below.
A24: Week 8 retest target — 2026-11-11
A25: Scenario | B25: 20 min avg | C25: FTP | D25: W/kg
A26: Now (Oct 1) | B26: 196 W | C26: 186 W | D26: 2.56 W/kg
A27: Good — +5% | B27: 206 W | C27: 195 W | D27: 2.69 W/kg
A28: Strong — +10% | B28: 216 W | C28: 205 W | D28: 2.82 W/kg
A29: Pace it evenly this time. The whole test is a pacing exercise: the number you get is the number you could hold for the full twenty minutes, so a fast first five buys nothing and costs the last ten. Same bike, same warm-up, and open at the target rather than at what feels good.
A31: Why the winter bike block exists
A32: Metric | B32: Value
A33: Current | B33: 186 W
A34: Target | B34: 220–240 W
A35: Target W/kg | B35: 3.0–3.3 W/kg
A36: Deadline | B36: Victoria 70.3, late May 2027
A37: An 18–29% gain. That is a lot to ask of six weeks and an entirely reasonable ask of eight months, which is what there is — this block only has to deliver the first third of it.

Sheet Run
A1: Run ramp + lower-leg guardrails
A2: The ramp is the plan; the protocol is what keeps you in it. Actual km is pulled from the Log.
A4: Weekly ramp
A5: Week | B5: Dates | C5: Runs | D5: Planned volume | E5: Actual (from Log) | F5: Long run | G5: Note
A6: Week 1 | B6: Sep 21–27 | C6: 1 | D6: 5 km | E6: =IFERROR(SUMIFS(Log!$L$5:$L$400,Log!$C$5:$C$400,1),0) | F6: 5 km | G6: Pre-orthotic holding pattern. Track or soft trail only.
A7: Week 2 | B7: Sep 28–Oct 4 | C7: 1 | D7: 6 km | E7: =IFERROR(SUMIFS(Log!$L$5:$L$400,Log!$C$5:$C$400,2),0) | F7: 6 km | G7: Add 4 × 20 s strides on grass. Still one run.
A8: Week 3 | B8: Oct 5–11 | C8: 2 | D8: 9 km | E8: =IFERROR(SUMIFS(Log!$L$5:$L$400,Log!$C$5:$C$400,3),0) | F8: 5 km | G8: Second run only if the orthotics have arrived. If not, repeat Week 2.
A9: Week 4 | B9: Oct 12–18 | C9: 2 | D9: 11 km | E9: =IFERROR(SUMIFS(Log!$L$5:$L$400,Log!$C$5:$C$400,4),0) | F9: 6 km | G9: First week in orthotics — expect new calf soreness, that is normal.
A10: Week 5 | B10: Oct 19–25 | C10: 3 | D10: 13 km | E10: =IFERROR(SUMIFS(Log!$L$5:$L$400,Log!$C$5:$C$400,5),0) | F10: 5 km | G10: Third run added as three short runs, not one long one.
A11: Week 6 | B11: Oct 26–Nov 1 | C11: 3 | D11: 14 km | E11: =IFERROR(SUMIFS(Log!$L$5:$L$400,Log!$C$5:$C$400,6),0) | F11: 6 km | G11: New York all week. Two swims, no bike — running carries the week, long run Saturday.
A12: Week 7 | B12: Nov 2–8 | C12: 3 | D12: 12 km | E12: =IFERROR(SUMIFS(Log!$L$5:$L$400,Log!$C$5:$C$400,7),0) | F12: 5 km | G12: Down week. Flying home plus three swims in three days — running gives way.
A13: Week 8 | B13: Nov 9–15 | C13: 3 | D13: 16 km | E13: =IFERROR(SUMIFS(Log!$L$5:$L$400,Log!$C$5:$C$400,8),0) | F13: 8 km | G13: Long run reaches race distance for the first time.
A14: Week 9 | B14: Nov 16–22 | C14: 3 | D14: 18 km | E14: =IFERROR(SUMIFS(Log!$L$5:$L$400,Log!$C$5:$C$400,9),0) | F14: 10 km | G14: Peak run week. 10 km long run, comfortably over race distance.
A15: Week 10 | B15: Nov 23–29 | C15: 3 | D15: 15 km | E15: =IFERROR(SUMIFS(Log!$L$5:$L$400,Log!$C$5:$C$400,10),0) | F15: 7 km | G15: Edmonton down week. Ice and cold — indoor track is fine here.
A16: Week 11 | B16: Nov 30–Dec 6 | C16: 2 + race | D16: 16 km | E16: =IFERROR(SUMIFS(Log!$L$5:$L$400,Log!$C$5:$C$400,11),0) | F16: 8 km race | G16: Run-only taper. Swim and bike continue as normal; strength drops to Monday's full-body session only.
A17: Week 12 | B17: Dec 7–13 | C17: 3 | D17: 15 km | E17: =IFERROR(SUMIFS(Log!$L$5:$L$400,Log!$C$5:$C$400,12),0) | F17: 6 km | G17: Florida. Easy running in warm weather, no quality work.
A18: Week 13 | B18: Dec 14–20 | C18: 3 | D18: 17 km | E18: =IFERROR(SUMIFS(Log!$L$5:$L$400,Log!$C$5:$C$400,13),0) | F18: 8 km | G18: North Carolina gym week. Normal structure returns.
A19: Week 14 | B19: Dec 21–27 | C19: 3 | D19: 17 km | E19: =IFERROR(SUMIFS(Log!$L$5:$L$400,Log!$C$5:$C$400,14),0) | F19: 8 km | G19: Edmonton. Holiday gym hours — check before planning.
A20: Week 15 | B20: Dec 28–31 | C20: 2 | D20: 13 km | E20: =IFERROR(SUMIFS(Log!$L$5:$L$400,Log!$C$5:$C$400,15),0) | F20: 8 km | G20: Close the block. Carry a run base into January, do not rebuild it.
A22: Lower-leg protocol — the non-negotiables
A23: Rule
A24: Soleus is the shin-splint muscle: bent-knee calf raises matter more than straight-leg ones. Full body A carries the straight-leg standing raise, Full body B the bent-knee seated raise at the bigger dose.
A25: Tibialis raises, 3 × 20, directly load the anterior compartment — the CECS one. Never skip these.
A26: Knee-to-wall ankle dorsiflexion test each Monday; target 10–12 cm. Losing range is an early warning.
A27: Run cadence 175–180 spm. Higher cadence cuts tibial bone load at the same pace and is the cheapest injury insurance you have.
A28: Surface priority: track > soft trail > gravel path > pavement. Pavement is the 25% trigger, so treat it as the exception.
A29: Never raise weekly run volume and the long run in the same week.
A30: Two-day rule: tightness that is still there 48 h after a run means the next run is cut, not pushed.
A31: Do not stretch aggressively into compartment pain — for CECS that makes it worse, not better.

Sheet Strength
A1: Strength templates + load log
A2: Log the weight you actually used so progression is visible.
A4: Full body A — hinge + pull
A5: Hamstrings, glutes, gastrocnemius, lats, rear shoulder.
A6: Exercise | B6: W1 | C6: W2 | D6: W3 | E6: W4 | F6: W5 | G6: W6 | H6: W7 | I6: W8 | J6: W9 | K6: W10 | L6: W11 | M6: W12 | N6: W13 | O6: W14 | P6: W15
A7: Warm-up · banded lateral walk 2 × 15 per side, then two ramp-up sets of the first lift
A8: A1 · Barbell Romanian deadlift — 4 × 6–8, 3 s eccentric
A9: A2 · Weighted pull-up or lat pulldown — 4 × 6–8
A10: B1 · Smith Bulgarian split squat — 3 × 8 per leg
A11: B2 · Straight-arm pulldown — 3 × 12
A12: C · Standing calf raise (straight leg) — 3 × 12, 3 s down
A13: C · Tibialis raise — 3 × 20
A14: C · Pallof press — 3 × 12 per side
A15: C · Face pull — 3 × 15
A18: Full body B — single-leg + press
A19: Quads, single-leg stability, soleus, adductors, chest, rotator cuff.
A20: Exercise | B20: W1 | C20: W2 | D20: W3 | E20: W4 | F20: W5 | G20: W6 | H20: W7 | I20: W8 | J20: W9 | K20: W10 | L20: W11 | M20: W12 | N20: W13 | O20: W14 | P20: W15
A21: Warm-up · banded lateral walk 2 × 15 per side, then two ramp-up sets of the first lift
A22: A1 · Smith Bulgarian split squat — 4 × 8 per leg, heavier than Full body A
A23: A2 · Dumbbell bench press — 4 × 8
A24: B1 · Box step-up (18 in) — 3 × 10 per leg
A25: B2 · Chest-supported row — 3 × 10
A26: C · Seated calf raise (bent knee / soleus) — 4 × 15
A27: C · Tibialis raise — 3 × 20
A28: C · Copenhagen plank — 3 × 20–30 s per side
A29: C · Cable or band external rotation — 3 × 15 per side
A32: Bands + bodyweight circuit
A33: Full body with no barbell and no machines.
A34: Exercise | B34: W1 | C34: W2 | D34: W3 | E34: W4 | F34: W5 | G34: W6 | H34: W7 | I34: W8 | J34: W9 | K34: W10 | L34: W11 | M34: W12 | N34: W13 | O34: W14 | P34: W15
A35: Banded Romanian deadlift — 3 × 15
A36: Split squat — 3 × 12 per leg
A37: Single-leg calf raise — 3 × 15 per leg
A38: Tibialis raise — 3 × 20
A39: Band row — 3 × 15
A40: Push-up — 3 × 12
A41: Side plank with hip abduction — 3 × 10 per side

Sheet Reference
A1: Reference
A2: Phases, heart-rate zones, and what the block is for.
A4: Phases
A5: Dates | B5: Phase | C5: What it is for
A6: Sep 21 – Oct 11 | B6: Reset + measure | C6: Establish the 4-swim week and the send-off habit. Test CSS and FTP so the rest of the block has real numbers. Running stays at one run per week until the orthotics land — this is the non-negotiable part.
A7: Oct 12 – Nov 8 | B7: Build I — swim volume, run ramp | C7: Orthotics in: running goes to two, then three sessions a week at roughly +10%/wk. Swim threshold volume climbs. The New York trip (Oct 25 – Nov 3) runs as a travel block: two swims at the Chinatown YMCA hold the 6,000 yd floor, band circuits stand in for the lifts, and swims are back-loaded after the return.
A8: Nov 9 – Dec 6 | B8: Build II — peak swim, race specificity | C8: Highest swim volume of the block and the retest of CSS. Running adds short 5-mile-pace work, peaks with a 10 km long run, then takes a short run-only taper into the Dec 5 race. Swimming does not taper.
A9: Dec 7 – Dec 20 | B9: Travel maintenance | C9: Florida and North Carolina. Swims are front-loaded in Seattle Mon–Wed to protect the 6,000 yd streak, then the trip is run- and bodyweight-led until the North Carolina gym restores a normal week.
A10: Dec 21 – Dec 31 | B10: Winter base → January on-ramp | C10: Edmonton with full gym access. Rebuild the rhythm, close the block with a final CSS test, and hand a clean aerobic base to the Victoria 70.3 build.
A12: Heart-rate zones
A13: Zone | B13: Range | C13: Use
A14: Run — easy | B14: 140–152 bpm | C14: Every easy run lives here. If it drifts above, walk it back.
A15: Run — steady / tempo | B15: 158–168 bpm | C15: Thursday quality only, and never for long early in the block.
A16: Bike — Z2 endurance | B16: 130–145 bpm | C16: Matches the Sep 17 outdoor ride (136 bpm avg). The Sep 23 spin ran 140–150, a touch hot — aim for the middle of the band, not the top.
A17: Bike — threshold | B17: 155–165 bpm | C17: Spin-bike intervals. Now paired with watts — see the FTP test log. Where the two disagree, trust the watts: power is what you did, heart rate is how you felt about it.
A19: Block at a glance
A20: Metric | B20: Value
A21: Block focus | B21: Swim engine
A22: Race | B22: 5 mile
A23: Lower-leg rule | B23: 1 run/wk
A24: Next block | B24: 70.3 prep
A26: Where things live
A27: Sheet | B27: What is on it
A28: Log | B28: Every session in the block. Tick Done, enter actuals, leave a note.
A29: Week Summary | B29: Rolls the log up by week — swim yards, run km, bike hours, sessions done.
A30: Swim | B30: CSS test log and retest target, pace zones, send-offs, drill phases, pre-swim checklist.
A31: Drills | B31: The drill library — gear, what you do, what to feel, what to watch for, and why.
A32: Bike | B32: FTP test log, live power zones, retest target, and the 70.3 power gap.
A33: Run | B33: The run ramp and its rules.
A34: Strength | B34: The lifting sessions, set by set.
